Workbook
Name ______________imp1: #REF!
Name ______________imp2: #REF!
Name ______________imp3: #REF!
Name ______________imp4: #REF!
Name ______________imp5: #REF!
Name ______________imp6: #REF!
Name _____________imp1: #REF!
Name _____________imp2: #REF!
Name _____________imp3: #REF!
Name _____________imp4: #REF!
Name _____________imp5: #REF!
Name _____________imp6: #REF!
Name ____________imp1: #REF!
Name ____________imp2: #REF!
Name ____________imp3: #REF!
Name ____________imp4: #REF!
Name ____________imp5: #REF!
Name ____________imp6: #REF!
Name ___________imp1: #REF!
Name ___________imp2: #REF!
Name ___________imp3: #REF!
Name ___________imp4: #REF!
Name ___________imp5: #REF!
Name ___________imp6: #REF!
Name __________imp1: #REF!
Name __________imp2: #REF!
Name __________imp3: #REF!
Name __________imp4: #REF!
Name __________imp5: #REF!
Name __________imp6: #REF!
Name _________imp1: #REF!
Name _________imp2: #REF!
Name _________imp3: #REF!
Name _________imp4: #REF!
Name _________imp5: #REF!
Name _________imp6: #REF!
Name ________imp1: #REF!
Name ________imp2: #REF!
Name ________imp3: #REF!
Name ________imp4: #REF!
Name ________imp5: #REF!
Name ________imp6: #REF!
Name _______imp1: #REF!
Name _______imp2: #REF!
Name _______imp3: #REF!
Name _______imp4: #REF!
Name _______imp5: #REF!
Name _______imp6: #REF!
Name ______imp1: #REF!
Name ______imp2: #REF!
Name ______imp3: #REF!
Name ______imp4: #REF!
Name ______imp5: #REF!
Name ______imp6: #REF!
Name _____imp1: #REF!
Name _____imp2: #REF!
Name _____imp3: #REF!
Name _____imp4: #REF!
Name _____imp5: #REF!
Name _____imp6: #REF!

Sheet Cover Page.
C4: GOVERNMENT OF TELANGANA
C11: IRRIGATION & CAD DEPARTMENT
B15: Name of work:- Construction of S.L.R.B. across Mulakala kalva Major near L-8 Minor off-take at KM 5.506 (Reach-IV) in Yadgarpalli village of Miryalaguda Mandal, Nalgonda District.
C17: AMOUNT OF ESTIMATE
B18: , | F18: Rs | G18: ='Gen Abst'!C18 -> 37.7 | I18: Lakhs

Sheet Check slip - TS
A1: CHECK SLIP ACCOMPANYING THE PROJECT / SCHEME / WORK ESTIMATE
A3: 1 | B3: Name of the Project /Scheme/Work | C3: : | D3: Construction of S.L.R.B. across Mulakala kalva Major near L-8 Minor off-take at KM 5.506 (Reach-IV) in Yadgarpalli village of Miryalaguda Mandal, Nalgonda District.
A4: 2 | B4: Estimate Amount Rs. | C4: : | D4: 37.70 Lakhs
A5: 3 | B5: Category of Project /Scheme /Work | C5: : | D5: Nagarjuna Sagar Project
A6: 4 | B6: Location /District /Mandal /Village | C6: : | D6: Yadgarpalli Village,Miryalaguda Mandal,Nalgonda Dist.,
A7: 5 | B7: Scope of work in brief | C7: : | D7: Construction of single vent S.L.R.B. of 9.0 m clear span with 6.0 m carriageway across Mulakala kalva Major at Km 5.506
A8: 6 | B8: Ayacut proposed - Wet/ID | C8: : | D8: No new ayacut (serves existing L-8 Minor ayacut of 357.32 Ac)
A9: 7 | B9: Cropping pattern | C9: : | D9: Paddy/Cotton
A10: 8 | B10: Source /River basin /Sub-basin /Sub-Minor basin | C10: : | D10: Krishna Basin/Nagarjuna Sagar Project
A11: 9 | B11: Availability of water at the site | C11: : | D11: -
A12: 10 | B12: Allocation of water /utilization | C12: : | D12: -
A13: 11 | B13: Reference in which Hydrological clearance was accorded by the competent authority | C13: : | D13: -
A14: 12 | B14: Cost per Acre Rs. | C14: : | D14: -
... A24: 22 | B24: Whether the lead statement with certificates is enclosed | C24: : | D24: YES
D25: Contd..2
A26: Page No.2
A28: 23 | B28: Whether Borrow area /quarry maps are enclosed | C28: : | D28: YES
A29: 24 | B29: Whether the amount of labour component and certificate of L.A. & L.I. furnished | C29: : | D29: Not required
A30: 25 | B30: Whether geological and foundation investigations carried out | C30: : | D30: Trial pit to be taken before execution
A31: 26 | B31: Whether the extent of L.A./forest lands is furnished | C31: : | D31: Not required
A32: 27 | B32: Are the rates of L.A. adopted based on the certificate issued by the Revenue Authorities. | C32: : | D32: Not required
A33: 28 | B33: Whether provision for compensatory afforestation and NPV is provided in consultation with Forest dept. | C33: : | D33: -
A34: 29 | B34: Whether the cost for CM & CD works is based on cost curves updated with current SSR | C34: : | D34: Not applicable
A35: 30 | B35: Whether provision for distributaries and field channels is based on the estimate prepared for a model block covering 10% of the command | C35: : | D35: -
A36: 31 | B36: Whether provisions made for dewatering and other LS provisions are reasonable | C36: : | D36: -
A37: 32 | B37: Whether the provision for formation of road, NH crossing, railway crossing and other road crossings is based on their specification and standards. | C37: : | D37: YES (as per IRC codes)
A38: 33 | B38: Whether the site was inspected by the competent authority before submitting the estimates as indicated below. If so furnish the date of inspection and confirm whether the estimate is prepared keeping in view the observations. | C38: : | D38: YES
A39: i) | B39: Upto Rs.50.00 Lakhs EE | C39: : | D39: YES
... A47: 39 | B47: Q.C. check authority proposed for this work | C47: : | D47: YES
A48: 39 | B48: Q.C. check authority proposed for this work | C48: : | D48: YES

Sheet Gen Abst
A1: GENERAL ABSTRACT
A2: =Abstract!A3 -> Name of work:- Construction of S.L.R.B. across Mulakala kalva Major near L-8 Minor off-take at KM 5.506 (Reach-IV) in Yadgarpalli village of Miryalaguda Mandal, Nalgonda District.
A3: S.No | B3: DESCRIPTION OF WORK | C3: Amount in Rs.
B4: Part A (Item Works)
A5: 1 | B5: Total ECV Amount | C5: =Abstract!G15 -> 3076801
B6: Total Rs. | C6: =SUM(C5:C5) -> 3076801
B7: Part B
A8: 2 | B8: LS Provision for Labour Cess @ 1 % | C8: =C6*1% -> 30768.01
A9: 3 | B9: LS Provision for NAC @ 0.1 % | C9: =+ROUND(C6*0.1%,0) -> 3077
A10: 4 | B10: LS Provision for Seigniorage Charges | C10: =seignorage!H19 -> 39474
A11: 5 | B11: DMF Provision @ 30 % for Seigniorage Charges | C11: =ROUND(2%*C10,0) -> 789
A12: 6 | B12: SMET Provision @ 2 % for Seigniorage Charges | C12: =seignorage!H20 -> 11842
A13: 7 | B13: Provision towards Permit Charges @ 80 % for Seigniorage Charges | C13: =seignorage!H24 -> 29633.6
B14: Sub Total | C14: =SUM(C8:E13) -> 115583.61
A15: 7 | B15: Add 18.00% GST on (Part A+Part B) | C15: =(C6+C14)*18% -> 574629.23
A16: 8 | B16: Rounding off and unforseen expenditure | C16: =ROUNDUP((C6+C14+C15)/1000,0)*1000-(C6+C14+C15)+2000 -> 2986.1602
B17: Total Rs. | C17: =C16+C15+C14+C6 -> 3770000
B18: Or Say (LAKHS) | C18: =C17/100000 -> 37.7
C65516: 46356

Sheet Abstract
A1: ABSTRACT
A3: ='detailed '!A3:I3 -> Name of work:- Construction of S.L.R.B. across Mulakala kalva Major near L-8 Minor off-take at KM 5.506 (Reach-IV) in Yadgarpalli village of Miryalaguda Mandal, Nalgonda District.
A5: Sl.No. | B5: Item Code | C5: Description of Item | D5: Qty | E5: Rate | F5: Unit | G5: Amount in Rs.
A6: 1 | B6: 2 | C6: 3 | D6: 4 | E6: 5 | F6: 6 | G6: 7
A7: 1 | B7: IRR-CCDW-1-2 | C7: Earth work in excavation in all kinds of soils of foundation of structures as per drawing and technical specification, including setting out, shoring and bracing, dressing of sides and bottom and backfilling with approved material. | D7: ='detailed '!I14 -> 512.997 | E7: ='DATA-26-27'!H40 -> 136.9 | F7: Cum | G7: =ROUND(D7*E7,0) -> 70229
A8: 2 | B8: IRR-CCDW-2-3 | C8: Providing and laying insitu vibrated M-15 grade cement concrete using 40 mm down size graded aggregates for foundation filling, complete with initial lead upto 50 m and all lifts. | D8: ='detailed '!I22 -> 66.475 | E8: ='DATA-26-27'!H110 -> 6698 | F8: Cum | G8: =ROUND(D8*E8,0) -> 445250
A9: 3 | B9: IRR-CCDW-2-9 | C9: Providing and laying insitu vibrated M-15 grade cement concrete using 20 mm down size graded aggregates for bed apron & canal lining, complete with initial lead upto 50 m and all lifts. | D9: ='detailed '!I28 -> 41.465 | E9: ='DATA-26-27'!H182 -> 7042 | F9: Cum | G9: =ROUND(D9*E9,0) -> 291997
A10: 4 | B10: IRR-CCDW-2-22 | C10: Providing and laying insitu vibrated M-15 grade cement concrete using 40 mm down size graded aggregates with placing and sinking plums upto 15 percent for abutments, wing & return walls, complete. | D10: ='detailed '!I35 -> 120.024 | E10: ='DATA-26-27'!H274 -> 7826 | F10: Cum | G10: =ROUND(D10*E10,0) -> 939308
A11: 5 | B11: IRR-CCDW-2-1 | C11: Providing, fabricating and placing in position reinforcement steel bars for RCC works including cleaning, straightening, cutting, bending, lapping, tying etc., complete (as per BBS). | D11: ='detailed '!I38 -> 4938.74 | E11: ='DATA-26-27'!H314 -> 82.4 | F11: kg | G11: =ROUND(D11*E11,0) -> 406952
A12: 6 | B12: IRR-CCDW-2-10 | C12: Providing and laying insitu vibrated M-20 grade cement concrete using 20 mm down size graded aggregates for bed blocks & dirt walls, complete with initial lead upto 50 m and all lifts. | D12: ='detailed '!I44 -> 6.676 | E12: ='DATA-26-27'!H386 -> 7876 | F12: Cum | G12: =ROUND(D12*E12,0) -> 52580 | H12: M-20 data rate - replace with M-25
A13: 7 | B13: IRR-CCDW-2-25 | C13: Providing and laying insitu vibrated M-20 grade cement concrete using 20 mm down size graded aggregates for deck slab, kerb, parapet & approach slabs, complete with initial lead upto 50 m and all lifts. | D13: ='detailed '!I52 -> 72.375 | E13: ='DATA-26-27'!H469 -> 11609 | F13: Cum | G13: =ROUND(D13*E13,0) -> 840201 | H13: M-20 data rate - replace with M-25
A14: 8 | B14: IRR-CCDW-2-9 | C14: Providing and laying VCC M-20 grade wearing coat 75 mm thick over deck slab, complete. | D14: ='detailed '!I56 -> 4.5 | E14: ='DATA-26-27'!H551 -> 6729.7 | F14: Cum | G14: =ROUND(D14*E14,0) -> 30284 | H14: M-20 data rate - replace with M-25
F15: ECV | G15: =SUM(G7:G14) -> 3076801

Sheet detailed 
A1: Detailed Estimate
A3: Name of work:- Construction of S.L.R.B. across Mulakala kalva Major near L-8 Minor off-take at KM 5.506 (Reach-IV) in Yadgarpalli village of Miryalaguda Mandal, Nalgonda District.
A4: S.No. | B4: Description of Item | C4: No | F4: Length | G4: Width | H4: Depth | I4: Qty | J4: Unit
B6: IRR-CCDW-1-2
A7: 1 | B7: Earth work in excavation in all kinds of soils of foundation of structures as per drawing and technical specification, including setting out, construction of shoring and bracing, removal of stumps and other deleterious matter, dressing of sides and bottom and backfilling with approved material.
B8: S.L.R.B. @ Km 5.506
B9: For abutments | C9: 1 | D9: x | E9: 2 | F9: 7.65 | G9: 4.1 | H9: 2.725 | I9: =ROUND(C9*E9*F9*G9*H9,3) -> 170.939
B10: for wing walls | C10: 1 | D10: x | E10: 4 | F10: 4.1 | G10: 3.8 | H10: 2.725 | I10: =ROUND(C10*E10*F10*G10*H10,3) -> 169.822
B11: for return walls | C11: 1 | D11: x | E11: 4 | F11: 2.6 | G11: 3.8 | H11: 2.725 | I11: =ROUND(C11*E11*F11*G11*H11,3) -> 107.692
B12: bed & slope trimming for apron / lining | C12: 1 | D12: x | E12: 1 | F12: 39 | G12: 9.905 | H12: 0.15 | I12: =ROUND(C12*E12*F12*G12*H12,3) -> 57.944
B13: for shear keys below wing & return footings | C13: 1 | D13: x | E13: 4 | F13: 5.5 | G13: 0.5 | H13: 0.6 | I13: =ROUND(C13*E13*F13*G13*H13,3) -> 6.6
H14: Total | I14: =SUM(I9:I13) -> 512.997 | J14: Cum
B15: IRR-CCDW-2-3
A16: 2 | B16: Providing and laying insitu vibrated M-15 ( 28 days cube compressive strength not less than15 N / sq mm ) grade cement concrete using 40 mm down size approved, clean, hard, gradedaggregates for foundation filling including cost of all materials, machinery, labour, formwork,cleaning, batching, mixing, placing in position, levelling, vibrating, finishing, curing etc.complete with initial lead upto 50 m and all lifts. (Cement content: 260 kg / cum with use of super plasticiser(0.4% by wt. of cement), CA : 0.90cum, Blending Ratio of CA--50:30:20, FA : 0.40 cum)
B17: S.L.R.B. @ Km 5.506
B18: For abutment foundation | C18: 1 | D18: x | E18: 2 | F18: 7.05 | G18: 3.5 | H18: 0.5 | I18: =ROUND(C18*E18*F18*G18*H18,3) -> 24.675
B19: for wing walls | C19: 1 | D19: x | E19: 4 | F19: 3.5 | G19: 3.2 | H19: 0.5 | I19: =ROUND(C19*E19*F19*G19*H19,3) -> 22.4
B20: for return walls | C20: 1 | D20: x | E20: 4 | F20: 2 | G20: 3.2 | H20: 0.5 | I20: =ROUND(C20*E20*F20*G20*H20,3) -> 12.8
B21: for shear keys under wing & return walls | C21: 1 | D21: x | E21: 4 | F21: 5.5 | G21: 0.5 | H21: 0.6 | I21: =ROUND(C21*E21*F21*G21*H21,3) -> 6.6
H22: Total | I22: =SUM(I18:I21) -> 66.475 | J22: Cum
B23: IRR-CCDW-2-9
A24: 3 | B24: Providing and laying insitu vibrated M-15 ( 28 days cube compressive strength not less than 15 N / sq mm ) grade cement concrete using 40 mm down size approved, clean, hard, graded aggregates for sub-structure / super- structure works including cost of all materials,machinery, labour, formwork, scaffolding, cleaning, batching, mixing, placing in position,evelling, vibrating, finishing, curing etc., complete with initial lead upto 50 m and all lifts.(Cement content: 280 kg / cum with use of super plasticiser(0.4% by wt. of cement),CA : 0.90cum, Blending Ratio of CA--50:30:20, FA : 0.40 cum)
B25: S.L.R.B. @ Km 5.506
B26: Bed apron in between abutments (150 thk) | C26: 1 | D26: x | E26: 1 | F26: 9 | G26: 6.45 | H26: 0.15 | I26: =ROUND(C26*E26*F26*G26*H26,3) -> 8.708
B27: CC lining bed & slopes u/s & d/s 15 m each (100 thk) | C27: 1 | D27: x | E27: 2 | F27: 15 | G27: 10.919 | H27: 0.1 | I27: =ROUND(C27*E27*F27*G27*H27,3) -> 32.757
H28: Total | I28: =SUM(I26:I27) -> 41.465 | J28: Cum
B29: IRR-CCDW-2-22
A30: 4 | B30: Providing and laying insitu vibrated M-15 ( 28 days cube compressive strength not less than15 N / sq mm ) grade cement concrete using 40 mm down size approved, clean, hard, gradedaggregates with placing and sinking plums of size 150 to 80 mm upto 15 percent for gravitytype retaining walls / piers / abutments etc., including cost of all materials, machinery,labour, formwork, scaffolding, cleaning, batching, mixing, placing in position, levelling, vibrating,finishing, curing etc.,complete with initial lead upto 50 m and all lifts.
B31: S.L.R.B. @ Km 5.506
B32: For abutments (1.00+2.00)/2 | C32: 1 | D32: x | E32: 2 | F32: 6.45 | G32: 1.5 | H32: 1.925 | I32: =ROUND(C32*E32*F32*G32*H32,3) -> 37.249
B33: for wing walls (0.60+2.20)/2 | C33: 1 | D33: x | E33: 4 | F33: 3.5 | G33: 1.4 | H33: 2.6875 | I33: =ROUND(C33*E33*F33*G33*H33,3) -> 52.675
B34: for return walls (0.60+2.20)/2 | C34: 1 | D34: x | E34: 4 | F34: 2 | G34: 1.4 | H34: 2.6875 | I34: =ROUND(C34*E34*F34*G34*H34,3) -> 30.1
H35: Total | I35: =SUM(I32:I34) -> 120.024 | J35: Cum
B36: IRR-CCDW-2-1
A37: 5 | B37: Providing, fabricating and placing in position reinforcement steel bars for RCC works including cleaning, straightening, cutting, bending, hooking, lapping, welding wherever required,tying with 1.25 mm dia soft annealed steel wire, including cost of all materials, machinery, labour etc., complete with initial lead upto 50 and all lifts.
B38: Qty sheet enclosed (Bar Bending Schedule) | I38: =steel!K29 -> 4938.74 | J38: kgs
B39: IRR-CCDW-2-10
A40: 6 | B40: Providing and laying insitu vibrated M-20 ( 28 days cube compressive strength not less than20 N / sq mm ) grade cement concrete using 20 mm down size approved, clean, hard, gradedaggregates for sub-structure / super- structure works including cost of all materials,machinery, labour, formwork, scaffolding, cleaning, batching, mixing, placing in position,levelling, vibrating, finishing, curing etc., complete with initial lead upto 50 m and all lifts.
B41: S.L.R.B. @ Km 5.506
B42: for bed blocks on abutments | C42: 1 | D42: x | E42: 2 | F42: 6.45 | G42: 0.5 | H42: 0.3 | I42: =ROUND(C42*E42*F42*G42*H42,3) -> 1.935
...

Sheet DATA-26-27
A1: DATA SSR 2026-27
A2: Sl.No | B2: Item Code | C2: Description | E2: Unit | F2: Quantity | G2: Rate | H2: Amount
A3: 1 | B3: IRR-CCDW-1-2 | C3: Earth work in excavation in all kinds of soils of foundation of structures as per drawing and technical specification, including setting out, construction of shoring and bracing, removal of stumps and other deleterious matter, dressing of sides and bottom and backfilling with approved material.
C6: Depth upto 3 m
C7: Unit = cum | L7: s
B8: DATA: | C8: Taking output = 240 cum | E8: Unit | F8: 240 | G8: cum
C9: A. Materials:
C10: Sl No | D10: Description | E10: Unit | F10: Quantity | G10: Rate | H10: Amount
G11: in Rs. | H11: in Rs.
D12: NIL | F12: 0 | G12: 0 | H12: 0
C14: B. Machinery:
C15: Sl No | D15: Description | E15: Unit | F15: Quantity | G15: Rate | H15: Amount
G16: in Rs. | H16: in Rs.
C17: 1 | D17: Hydraulic excavator 1.0 cum bucket capacity | E17: hour | F17: 6 | G17: 1964.8 | H17: =G17*F17 -> 11788.8
D18: Fuel/ Energy charges | E18: hour | F18: 6 | G18: 1570.3 | H18: =G18*F18 -> 9421.8
D19: Total in Rs. | H19: =SUM(H17:H18) -> 21210.6
C21: C. Labour:
C22: Sl No | D22: Description | E22: Unit | F22: Quantity | G22: Rate | H22: Amount
G23: in Rs. | H23: in Rs.
C24: 1 | D24: work inspector | E24: day | F24: 0.32 | G24: 845 | H24: =G24*F24 -> 270.4
C25: 2 | D25: Mazdoor | E25: day | F25: 8 | G25: 635 | H25: =G25*F25 -> 5080
C26: 3 | D26: crew for excavator | E26: hour | F26: 6 | G26: 392.6 | H26: =G26*F26 -> 2355.6
D27: Total in Rs. | H27: =SUM(H24:H26) -> 7706
C28: labour component/unit qty | F28: =H27/240 -> 32.108333
C29: Add contractor's profit and overhead charges | E29: 0.13615 | F29: =E29*F28 -> 4.3715496
C30: labour component/unit qty (including contractor's profit) | F30: =SUM(F28:F29) -> 36.479883
C32: Abstract
C33: a) Material | G33: Rs | H33: 0
C34: b) Machinery | G34: Rs | H34: =H19 -> 21210.6
C35: c) Labour | G35: Rs | H35: =H27 -> 7706
C36: Total | G36: Rs | H36: =SUM(H33:H35) -> 28916.6
C37: D. Add for contractor's profit and overheads on (A+B+C) | F37: 0.13615 | G37: Rs: | H37: =F37*H36 -> 3936.9951
C38: Total cost for | E38: 240 | F38: cum | G38: Rs: | H38: =SUM(H36:H37) -> 32853.595
C39: Rate per cum | E39: (A+B+C+D)/240.0 | G39: Rs. | H39: =H38/240 -> 136.88998
G40: say | H40: =ROUND(H39,1) -> 136.9
A41: 2 | B41: IRR-CCDW-2-3 | C41: Providing and laying insitu vibrated M-15 ( 28 days cube compressive strength not less than15 N / sq mm ) grade cement concrete using 40 mm down size approved, clean, hard, gradedaggregates for foundation filling including cost of all materials, machinery, labour, formwork,cleaning, batching, mixing, placing in position, levelling, vibrating, finishing, curing etc.complete with initial lead upto 50 m and all lifts. (Cement content: 260 kg / cum with use of super plasticiser(0.4% by wt. of cement), CA : 0.90cum, Blending Ratio of CA--50:30:20, FA : 0.40 cum)
B49: DATA:
D50: RATE ANALYSIS | F50: UNIT : | G50: 15.38 | H50: cum
C51: A. MATERIALS:
C52: Sl No | D52: Particulars | E52: Unit | F52: Quantity | G52: Rate | H52: Amount
...

Sheet seignorage
A1: Seigniorage Calculation
A2: =Abstract!A3 -> Name of work:- Construction of S.L.R.B. across Mulakala kalva Major near L-8 Minor off-take at KM 5.506 (Reach-IV) in Yadgarpalli village of Miryalaguda Mandal, Nalgonda District.
A5: S.No | B5: Specification in Brief | D5: Unit | F5: Quantity | G5: Earth/ Gravel | I5: Metal/ Stone | K5: NSand | M5: M Sand
G6: cum | I6: cum | M6: cum
G7: Factor | H7: Quantity | I7: Factor | J7: Quantity | K7: Factor | L7: Quantity | M7: Factor | N7: Quantity
A8: 1 | B8: 2 | D8: 3 | F8: 4 | G8: 5 | H8: 6 | I8: 7 | J8: 8 | K8: 9 | L8: 10 | M8: 11 | N8: 12
A9: 1 | B9: Earth work | D9: 1 | E9: 1 | I9: 0
A10: 1 | B10: M-15 (40 mm) foundation IRR-CCDW-2-3 | D10: 1 | E10: cum | F10: ='detailed '!I22 -> 66.475 | I10: 0.9 | J10: =F10*I10 -> 59.8275 | K10: 0.2 | L10: =F10*K10 -> 13.295 | M10: 0.2 | N10: =M10*F10 -> 13.295
A11: 2 | B11: M - 15 (20 mm) apron & lining IRR-CCDW-2-9 | D11: 1 | E11: cum | F11: ='detailed '!I28 -> 41.465 | I11: 0.9 | J11: =F11*I11 -> 37.3185 | K11: 0.2 | L11: =F11*K11 -> 8.293 | M11: 0.2 | N11: =M11*F11 -> 8.293
A12: 3 | B12: M - 15 (40 mm) with plums IRR-CCDW-2-22 | D12: 1 | E12: cum | F12: ='detailed '!I35 -> 120.024 | I12: 0.765 | J12: =F12*I12 -> 91.81836 | K12: 0.17 | L12: =F12*K12 -> 20.40408 | M12: 0.17 | N12: =M12*F12 -> 20.40408
A13: 4 | B13: M - 20 (20 mm) IRR-CCDW-2-10 | D13: 1 | E13: cum | F13: ='detailed '!I44 -> 6.676 | I13: 0.8 | J13: =F13*I13 -> 5.3408 | K13: 0.225 | L13: =F13*K13 -> 1.5021 | M13: 0.225 | N13: =M13*F13 -> 1.5021
A14: 5 | B14: M - 20 (20 mm) IRR-CCDW-2-25 Deck slab | D14: 1 | E14: cum | F14: ='detailed '!I52 -> 72.375 | I14: 0.8 | J14: =F14*I14 -> 57.9 | K14: 0.225 | L14: =F14*K14 -> 16.284375 | M14: 0.225 | N14: =M14*F14 -> 16.284375
A15: 6 | B15: M - 20 (20 mm) IRR-CCDW-2-29 + wearing coat | D15: 1 | E15: cum | F15: ='detailed '!I57 -> 4.5 | I15: 0.8 | J15: =I15*F15 -> 3.6 | K15: 0.225 | L15: =F15*K15 -> 1.0125 | M15: 0.225 | N15: =M15*F15 -> 1.0125
A16: Total Quantity | J16: =SUM(J10:J15) -> 255.80516 | L16: =SUM(L10:L15) -> 60.791055 | N16: =SUM(N10:N15) -> 60.791055
A17: Rate | J17: 117 | L17: 40 | N17: 117
A18: Amount Rs | H18: =ROUND(H17*H16,0) -> 0 | J18: =ROUND(J17*J16,0) -> 29929 | L18: =ROUND(L17*L16,0) -> 2432 | N18: =ROUND(N17*N16,0) -> 7113
A19: Total Rs | H19: =SUM(H18:N18) -> 39474
A20: DMF at 30 % on Seigniorage | H20: =ROUND(H19*0.3,0) -> 11842
A21: SMFT at 2 % on Signiorage | H21: =ROUND(H19*0.02,0) -> 789
H22: =SUM(H19:H21) -> 52105
A23: or say | H23: =ROUND(H22,0) -> 52105
B24: permit fee 80% on metal | H24: =(J18+N18)*80% -> 29633.6
A28: Assistant Executive Engineer | E28: Dy.Executive Engineer | J28: Executive Engineer
A29: Irr.Sub-Division No.3,Miryalaguda | E29: Irr.Sub-Division No.3,Miryalaguda | J29: Irr.Division No.3,Miryalaguda

Sheet lead chart
A1: Lead statement
A2: =seignorage!A2 -> Name of work:- Construction of S.L.R.B. across Mulakala kalva Major near L-8 Minor off-take at KM 5.506 (Reach-IV) in Yadgarpalli village of Miryalaguda Mandal, Nalgonda District.
A3: Sl. No. | B3: Name of Material | C3: Name of Source | D3: Unit | E3: SS No. | F3: Initial cost | G3: Distance | I3: Total Distance | J3: Initial Lead upto 1km | K3: Up to 5 Kms Lead | L3: for Every km beyond 5 km upto 30 km | M3: for Every km beyond 30 km | N3: For Every 1 km after 5 km | O3: Lead (km) | P3: Conveyance charges includes Contractors Profit & Over Head (13.615%) (Rs) | Q3: After deducting intial lead (Rs)
G4: MR | H4: CT
A5: 1 | B5: Cement | C5: Local | D5: 1 MT | F5: 5200 | G5: C. Memo.No.l46lcement & SteeyT3/July/202c27 Dated: 22-08-2026 | Q5: 5200
A6: 2 | B6: steel | C6: local | D6: 1 MT | Q6: 56000
A7: 3 | B7: Fine Aggregate | C7: Ravulapenta | D7: 1 Cum | E7: 27 a | F7: 777 | G7: 21 | H7: - | I7: 21 | J7: 48.2 | K7: 128.6 | L7: 19.3 | M7: 16.1 | O7: 21 | P7: =K7+(O7-5)*L7 -> 437.4 | Q7: =P7-J7 -> 389.2 | R7: =6*14.2 -> 85.2 | S7: =113.6+R7+#REF! -> #REF!
A8: 4 | B8: Manufacture sand | C8: Appanapeta | D8: 1 Cum | E8: 94 | F8: 727 | G8: 21 | I8: 21 | J8: 46.5 | K8: 128.6 | L8: 19.3 | M8: 16.1 | O8: 21 | P8: =K8+(O8-5)*L8 -> 437.4 | Q8: =P8-J8 -> 390.9
A9: 5 | B9: Coarse Aggregate 40 MM | C9: Appanapeta | D9: 1 Cum | E9: 9 | F9: 899 | G9: 21 | H9: - | I9: 21 | J9: 46.5 | K9: 128.6 | L9: 19.3 | M9: 16.1 | O9: 21 | P9: =K9+(O9-5)*L9 -> 437.4 | Q9: =P9-J9 -> 390.9
A10: 6 | B10: Coarse Aggregate 20 MM | C10: Appanapeta | D10: 1 Cum | E10: 8 | F10: 1000 | G10: 21 | H10: - | I10: =I9 -> 21 | J10: =J9 -> 46.5 | K10: =K9 -> 128.6 | L10: =L9 -> 19.3 | M10: =M9 -> 16.1 | O10: =O9 -> 21 | P10: =K10+(O10-5)*L10 -> 437.4 | Q10: =P10-J10 -> 390.9
A11: 7 | B11: Coarse Aggregate 10 MM | C11: Appanapeta | D11: 1 Cum | E11: 7 | F11: 768 | G11: 21 | H11: - | I11: 21 | J11: =J10 -> 46.5 | K11: =K10 -> 128.6 | L11: =L10 -> 19.3 | M11: =M10 -> 16.1 | O11: =O10 -> 21 | P11: =K11+(O11-5)*L11 -> 437.4 | Q11: =P11-J11 -> 390.9
A12: 8 | B12: Gravel | C12: M-008 | D12: Local | E12: Cum | F12: 109 | G12: 5 | J12: =J7 -> 48.2 | K12: 128.6 | L12: =L5 -> 0 | M12: =M6 -> 0 | O12: 5 | P12: =K12+(O12-5)*L12 -> 128.6 | Q12: =P12-J12 -> 80.4
A13: 1 | B13: Certified that the leads furnished above are correct to the best of my knowledge.
A14: 2 | B14: Certified that the blasting is necessary to obtain rubble and metal.

Sheet steel
A1: REINFORCEMENT STEEL
A2: BAR BENDING SCHEDULE
A3: Name of work:- Construction of S.L.R.B. across Mulakala kalva Major near L-8 Minor off-take at KM 5.506 (Reach-IV) in Yadgarpalli village of Miryalaguda Mandal, Nalgonda District.
A4: SLNO | B4: Description Of Bars | C4: Dia Of Bar (mm) | D4: Spacing (m) | E4: Shape / Length make-up | F4: Length (m) | G4: No of Bars | H4: No of Mem. | I4: Total Length (m) | J4: Weight Of Bar Per RMT (kg) | K4: Total Weight In Kgs
A5: 1 | B5: Deck slab (1 No.) 10.00 x 6.45 x 0.75 m - M25
B6: (i) Main bars - straight (bottom) | C6: 25 | D6: 0.25 | E6: Straight 10.00 - 2x0.04 | F6: =10-2*0.04 -> 9.92 | G6: =ROUNDUP((6.45-2*0.04)/D6,0)+1 -> 27 | H6: 1 | I6: =F6*G6*H6 -> 267.84 | J6: =ROUND(C6^2/162,3) -> 3.858 | K6: =ROUND(I6*J6,2) -> 1033.33
B7: (ii) Main bars - bent up (alternate) | C7: 25 | D7: 0.25 | E7: 2x2.36 + 2x0.912 (45°) + 3.910 | F7: =2*2.36+2*(0.75-2*0.04-0.025)*SQRT(2)+(10-2*0.04-2*2.36-2*(0.75-2*0.04-0.025)) -> 10.454335 | G7: =ROUNDUP((6.45-2*0.04)/D7,0) -> 26 | H7: 1 | I7: =F7*G7*H7 -> 271.81272 | J7: =ROUND(C7^2/162,3) -> 3.858 | K7: =ROUND(I7*J7,2) -> 1048.65
B8: (iii) Top bars (span direction) | C8: 12 | D8: 0.2 | E8: Straight | F8: =10-2*0.04 -> 9.92 | G8: =ROUNDUP((6.45-2*0.04)/D8,0)+1 -> 33 | H8: 1 | I8: =F8*G8*H8 -> 327.36 | J8: =ROUND(C8^2/162,3) -> 0.889 | K8: =ROUND(I8*J8,2) -> 291.02
B9: (iv) Distributaries - bottom | C9: 12 | D9: 0.11 | E9: Straight across width | F9: =6.45-2*0.04 -> 6.37 | G9: =ROUNDUP((10-2*0.04)/D9,0)+1 -> 92 | H9: 1 | I9: =F9*G9*H9 -> 586.04 | J9: =ROUND(C9^2/162,3) -> 0.889 | K9: =ROUND(I9*J9,2) -> 520.99
B10: (v) Distributaries - top | C10: 10 | D10: 0.3 | E10: Straight across width | F10: =6.45-2*0.04 -> 6.37 | G10: =ROUNDUP((10-2*0.04)/D10,0)+1 -> 35 | H10: 1 | I10: =F10*G10*H10 -> 222.95 | J10: =ROUND(C10^2/162,3) -> 0.617 | K10: =ROUND(I10*J10,2) -> 137.56
B11: (vi) Supporting chairs @ 1 No./sqm | C11: 12 | D11: - | E11: 2 legs 0.60 + 2 feet 0.15 | F11: 1.5 | G11: =ROUNDUP(10*6.45,0) -> 65 | H11: 1 | I11: =F11*G11*H11 -> 97.5 | J11: =ROUND(C11^2/162,3) -> 0.889 | K11: =ROUND(I11*J11,2) -> 86.68
A12: 2 | B12: Kerbs (2 Nos.) 0.225 x 0.30 m
B13: (i) Main bars | C13: 12 | D13: - | E13: Straight | F13: =10-2*0.04 -> 9.92 | G13: 4 | H13: 2 | I13: =F13*G13*H13 -> 79.36 | J13: =ROUND(C13^2/162,3) -> 0.889 | K13: =ROUND(I13*J13,2) -> 70.55
B14: (ii) Stirrups | C14: 8 | D14: 0.2 | E14: 2x(0.145+0.52) + 0.10 hooks | F14: =2*(0.225-2*0.04+0.3-2*0.04+0.3)+0.1 -> 1.43 | G14: =ROUNDUP((10-2*0.04)/D14,0)+1 -> 51 | H14: 2 | I14: =F14*G14*H14 -> 145.86 | J14: =ROUND(C14^2/162,3) -> 0.395 | K14: =ROUND(I14*J14,2) -> 57.61
A15: 3 | B15: RCC Parapet wall (2 Nos.) 0.20 x 0.90 m
B16: (i) Main bars | C16: 10 | D16: - | E16: Straight | F16: =10-2*0.04 -> 9.92 | G16: 4 | H16: 2 | I16: =F16*G16*H16 -> 79.36 | J16: =ROUND(C16^2/162,3) -> 0.617 | K16: =ROUND(I16*J16,2) -> 48.97 | P16: =SUM(K6:K11) -> 3118.23
B17: (ii) Stirrups | C17: 8 | D17: 0.2 | E17: 2x(0.12+0.82+0.30 anch.) + 0.10 | F17: =2*(0.2-2*0.04+0.9-0.04+0.3)+0.1 -> 2.66 | G17: =ROUNDUP((10-2*0.04)/D17,0)+1 -> 51 | H17: 2 | I17: =F17*G17*H17 -> 271.32 | J17: =ROUND(C17^2/162,3) -> 0.395 | K17: =ROUND(I17*J17,2) -> 107.17 | P17: =K13+K14 -> 128.16
A18: 4 | B18: Bed block over abutment (2 Nos.) 6.45 x 0.50 x 0.30 m
B19: (i) Main Bars (5 T + 5 B) | C19: 12 | D19: - | E19: Straight | F19: =6.45-2*0.04 -> 6.37 | G19: 10 | H19: 2 | I19: =F19*G19*H19 -> 127.4 | J19: =ROUND(C19^2/162,3) -> 0.889 | K19: =ROUND(I19*J19,2) -> 113.26
B20: (ii) Distributaries (stirrups) | C20: 12 | D20: 0.135 | E20: 2x(0.42+0.22) + 0.24 hooks | F20: =2*(0.5-2*0.04+0.3-2*0.04)+0.24 -> 1.52 | G20: =ROUNDUP((6.45-2*0.04)/D20,0)+1 -> 49 | H20: 2 | I20: =F20*G20*H20 -> 148.96 | J20: =ROUND(C20^2/162,3) -> 0.889 | K20: =ROUND(I20*J20,2) -> 132.43
A21: 5 | B21: Dirt wall (2 Nos.) 6.45 x 0.30 x 1.125 m
B22: (i) Vertical bars (both faces) | C22: 12 | D22: 0.2 | E22: 1.125 - 0.04 + 0.42 anchorage (Ld) | F22: =1.125-0.04+0.42 -> 1.505 | G22: =2*(ROUNDUP((6.45-2*0.04)/D22,0)+1) -> 66 | H22: 2 | I22: =F22*G22*H22 -> 198.66 | J22: =ROUND(C22^2/162,3) -> 0.889 | K22: =ROUND(I22*J22,2) -> 176.61
B23: (ii) Horizontal bars (both faces) | C23: 10 | D23: 0.2 | E23: Straight | F23: =6.45-2*0.04 -> 6.37 | G23: =2*(ROUNDUP((1.125-2*0.04)/D23,0)+1) -> 14 | H23: 2 | I23: =F23*G23*H23 -> 178.36 | J23: =ROUND(C23^2/162,3) -> 0.617 | K23: =ROUND(I23*J23,2) -> 110.05
A24: 6 | B24: Approach slab (2 Nos.) 3.50 x 6.00 x 0.30 m
B25: (I) Main bars (T&B) | C25: 12 | D25: 0.15 | E25: Straight | F25: =3.5-2*0.04 -> 3.42 | G25: =2*(ROUNDUP((6-2*0.04)/D25,0)+1) -> 82 | H25: 2 | I25: =F25*G25*H25 -> 560.88 | J25: =ROUND(C25^2/162,3) -> 0.889 | K25: =ROUND(I25*J25,2) -> 498.62
B26: (ii) Distributaries (T&B) | C26: 12 | D26: 0.15 | E26: Straight | F26: =6-2*0.04 -> 5.92 | G26: =2*(ROUNDUP((3.5-2*0.04)/D26,0)+1) -> 48 | H26: 2 | I26: =F26*G26*H26 -> 568.32 | J26: =ROUND(C26^2/162,3) -> 0.889 | K26: =ROUND(I26*J26,2) -> 505.24
J28: TOTAL | K28: =K6+K7+K8+K9+K10+K11+K13+K14+K16+K17+K19+K20+K22+K23+K25+K26 -> 4938.74
F29: TOTAL WEIGHT OF STEEL | K29: =+K28 -> 4938.74
B31: Dia-wise abstract
B32: Dia (mm) | C32: Wt (kg)
B33: 8 | C33: =SUMIF(C5:C27,B33,K5:K27) -> 164.78
B34: 10 | C34: =SUMIF(C5:C27,B34,K5:K27) -> 296.58
B35: 12 | C35: =SUMIF(C5:C27,B35,K5:K27) -> 2395.4
B36: 25 | C36: =SUMIF(C5:C27,B36,K5:K27) -> 2081.98
B37: Total | C37: =SUM(C33:C36) -> 4938.74
B44: Assistant Executive Engineer | E44: Dy.Executive Engineer | I44: Executive Engineer
B45: Irr.Sub-Division No.3,Miryalaguda | E45: Irr.Sub-Division No.3,Miryalaguda | I45: Irr.Division No.3,Miryalaguda

Sheet Quarry Map
A1: Name of Work : Construction of S.L.R.B. across Mulakalkalva Major near L-8 Minor off-take at Km 5.506 (Reach IV) in Yadgarpalli village of Miryalaguda Mandal, Nalgonda District.
A4: QUARRY MAP
B6: N
A46: Note: Map not to scale | G46: LEAD STATEMENT
G47: Material | I47: Source | J47: Lead (km)
G48: Metal & M-Sand | I48: Appanapeta | J48: 21
G49: Sand | I49: Ravulapenta | J49: 21
A60: Assistant Executive Engineer | F60: Deputy Executive Engineer | J60: Executive Engineer
A61: Irrigation Sub Division No.3, | F61: Irrigation Sub Division No.3, | J61: Irrigation Division No.3,
A62: Miryalaguda. | F62: Miryalaguda. | J62: Miryalaguda.

Sheet theoritical requirement
A1: Theoritical Requirement
A2: =#REF! -> #REF!
A3: Technical sanction No. | B3: -
A4: Agreement No. | B4: -
A5: Name of Contractor | B5: -
A7: 1.Theoritical requirement for Metal
A8: M-15 Grade (foundation) | C8: ='detailed '!I21 -> 6.6 | D8: x | E8: 0.9 | G8: =C8*E8 -> 5.94
A9: M-15 Grade (apron & lining) | C9: ='detailed '!I27 -> 32.757 | D9: x | E9: 0.9 | G9: =C9*E9 -> 29.4813
A10: M-15 Grade (with plums) | C10: ='detailed '!I34 -> 30.1 | D10: x | E10: 0.765 | G10: =C10*E10 -> 23.0265
A11: M-25 Grade (bed blocks & dirt wall) | C11: ='detailed '!I43 -> 4.741 | D11: x | E11: 0.8 | G11: =C11*E11 -> 3.7928
A12: M-25 Grade (deck, kerb, parapet, approach) | C12: ='detailed '!I51 -> 12.6 | D12: x | E12: 0.8 | G12: =C12*E12 -> 10.08
A13: M-25 Grade (wearing coat) | C13: ='detailed '!I56 -> 4.5 | D13: x | E13: 0.8 | G13: =C13*E13 -> 3.6
E14: Total | G14: =SUM(G8+G9+G10+G11+G12+G13) -> 75.9206 | H14: Cum
A15: 2.Theoritical requirement for Sand
A17: M-15 Grade (foundation) | C17: =C8 -> 6.6 | D17: x | E17: 0.4 | G17: =C17*E17 -> 2.64
A18: M-15 Grade (apron & lining) | C18: =C9 -> 32.757 | D18: x | E18: 0.4 | G18: =C18*E18 -> 13.1028
A19: M-15 Grade (with plums) | C19: =C10 -> 30.1 | D19: X | E19: 0.34 | G19: =C19*E19 -> 10.234
A20: M-25 Grade (bed blocks & dirt wall) | C20: =C11 -> 4.741 | D20: X | E20: 0.45 | G20: =C20*E20 -> 2.13345
A21: M-25 Grade (deck, kerb, parapet, approach) | C21: =C12 -> 12.6 | D21: x | E21: 0.45 | G21: =C21*E21 -> 5.67
A22: M-25 Grade (wearing coat) | C22: =C13 -> 4.5 | D22: x | E22: 0.45 | G22: =C22*E22 -> 2.025
E23: Total | G23: =SUM(G17:G22) -> 35.80525 | H23: Cum
A26: Asst .Executive Engineer | C26: Dy.Executive Engineer | G26: Executive Engineer
A27: Irrigation Sub-Division No.3 | C27: Irrigation Sub-Division No.3 | G27: Irrigation Division No.3
A28: Miryalaguda | C28: Miryalaguda | G28: Miryalaguda
