Workbook
Name \A: #REF!
Name \C: #REF!
Name \H: #REF!
Name \M: #REF!
Name \Z: #REF!
Name __________________________bla1: [1]leads!$H$7
Name __________________________l1: [2]leads!$A$3:$E$108
Name __________________________l12: #REF!
Name __________________________l12: #REF!
Name __________________________l12: #REF!
Name __________________________l12: #REF!
Name __________________________l12: #REF!
Name __________________________l12: #REF!
Name __________________________l12: #REF!
Name __________________________l3: #REF!
Name __________________________l3: #REF!
Name __________________________l3: #REF!
Name __________________________l4: [3]Sheet1!$W$2:$Y$103
Name __________________________l5: #REF!
Name __________________________l5: #REF!
Name __________________________l5: #REF!
Name __________________________l5: #REF!
Name __________________________l5: #REF!
Name __________________________l5: #REF!
Name __________________________l5: #REF!
Name __________________________mm1: [4]r!$F$4
Name __________________________rr3: [5]v!$A$2:$E$51
Name __________________________rrr1: [5]r!$B$1:$I$145
Name __________________________ss12: [6]rdamdata!$J$8
Name __________________________ss20: [6]rdamdata!$J$7
Name __________________________ss40: [6]rdamdata!$J$6
Name __________________________var1: #REF!
Name __________________________var1: #REF!
Name __________________________var1: #REF!
Name __________________________var1: #REF!
Name __________________________var1: #REF!
Name __________________________var1: #REF!
Name __________________________var1: #REF!
Name __________________________var4: #REF!
Name __________________________var4: #REF!
Name __________________________var4: #REF!
Name _________________________SS12: [7]Sheet1!$C$8
Name _________________________SS20: [7]Sheet1!$C$9
Name _________________________SS40: [7]Sheet1!$C$11
Name ________________________bla1: [1]leads!$H$7
Name ________________________l1: [2]leads!$A$3:$E$108
Name ________________________l12: #REF!
Name ________________________l12: #REF!
Name ________________________l12: #REF!
Name ________________________l12: #REF!
Name ________________________l12: #REF!
Name ________________________l12: #REF!
Name ________________________l12: #REF!
Name ________________________l3: #REF!
Name ________________________l3: #REF!
Name ________________________l3: #REF!
Name ________________________l4: [3]Sheet1!$W$2:$Y$103
Name ________________________l5: #REF!
Name ________________________l5: #REF!
Name ________________________l5: #REF!

Sheet Check slip
A1: CHECK SLIP ACCOMPANYING THE PROJECT/SCHEME/WORK ESTIMATE
A2: 1 | B2: Name of the Project /Scheme/Work | C2: : | D2: Name of Work : Repairs and Reconstruction of the Protection Wall and Inlet/Outlet Wing Walls of the U.T. at Km 8.388 of Mulkalakalva Major of NSLBC, Block-IV, at Alagadapa (V), Miryalaguda (M), Nalgonda District.
A3: 2 | B3: Estimate Amount Rs. | C3: : | D3: ='Abstract '!G21 -> 978221.03
A4: 3 | B4: Category of Project /Scheme /Work | C4: : | D4: Major Irrigation (NSP)
A5: 4 | B5: Location /District /Mandal /Village | C5: : | D5: Nalgonda Dist,Miryalaguda Mandal,Alagadapa Village.
A6: 5 | B6: Scope of work in brief | C6: : | D6: Dismantling of collapsed SM wing walls and protection wall; reconstruction of wing walls (2 x 2 x 5.00 m) and protection wall (37.00 m) in CC M-15 over CC M-15 foundation; replacement of damaged 300 mm RCC pipes at both ends; bank restoration by casing embankment
A7: 6 | B7: Ayacut proposed - Wet/ID | C7: : | D7: Wet and ID
A8: 7 | B8: Cropping pattern | C8: : | D8: paddy/Cotton
A9: 8 | B9: Source /River basin /Sub-basin /Sub-Minor basin | C9: : | D9: Nagarjuna Sagar Project
A10: 9 | B10: Availability of water at the site | C10: : | D10: -
A11: 10 | B11: Allocation of water /utilization | C11: : | D11: -
A12: 11 | B12: Reference in which Hydrological clearance was accorded by the competent authority | C12: : | D12: -
A13: 12 | B13: Cost per Acre Rs. | C13: : | D13: -
A14: 13 | B14: B.C. Ratio | C14: : | D14: -
A15: 14 | B15: Whether the report accompanying the estimate, detailed estimate and abstreact estimate are enclosed | C15: : | D15: YES
... A23: 22 | B23: Whether the lead statemet with certificates is enclosed | C23: : | D23: YES
D25: Contd..2
A27: Page No.2
A29: 23 | B29: Whether Barrow area /quarry mapsare enclosed | C29: : | D29: NA
A30: 24 | B30: Whether the amount of labour component and certificate of L.A. & L.I. furnished | C30: : | D30: Not required
A31: 25 | B31: Whether geological and foundation investigations carried out | C31: : | D31: Not required
A32: 26 | B32: Whether the extent of L.A./forest lands is furnished | C32: : | D32: Not required
A33: 27 | B33: Are the rates of L.A. adopted based on the certificate issued by the Revenue Authorities. | C33: : | D33: Not required
A34: 28 | B34: Whether provision for compensatory afforestration and NPV isprovided in consultation with Forest dept. | C34: : | D34: -
A35: 29 | B35: Whether the cost for CM & CD works in based on costcurves updated with current SSR | C35: : | D35: YES
A36: 30 | B36: Whether provision for distributaries and filed channels is based on the estimate prepared for a model block covering 10% of the command | C36: : | D36: -
A37: 31 | B37: Whether provisions made for dewatering and other LS provisions are reasonable | C37: : | D37: -
A38: 32 | B38: Whether the provision for formation of road, NH crossing, railway crossing and other road crossings isbased on their specification and standards. | C38: : | D38: --
A39: 33 | B39: Whether the site was inspected by the competent authority beforesubmitting the estimates asindicated below. If so furnishthedate of inspection and confirm whether the estimate is prepared keeping in view the observations. | C39: : | D39: YES
A40: i) | B40: Upto Rs.10.00 Lakhs EE | C40: : | D40: YES
A41: ii) | B41: Rs.10.00 Lakhs to Rs.50.00 Lakhs | C41: : | D41: --
A42: iii) | B42: Above 50.00 Lakhs ENC/CE | C42: : | D42: --
A43: 34 | B43: Are the detailed estimates /DATAs checked in Ses office | C43: : | D43: YES
A44: 35 | B44: Are the provisions examined /Abstract estimatechecked in CEs Office | C44: : | D44: YES
A45: 36 | B45: Whether the check slip for Admn.approval is enclosed | C45: : | D45: YES
A46: 37 | B46: Whether all officers upto CE signed | C46: : | D46: YES
A47: 38 | B47: Construction programe of the Project/Scheme/work | C47: : | D47: 3 months
A48: 39 | B48: Q.C. check authority proposed for this work | C48: : | D48: YES

Sheet COVER (2)
D4: GOVERNMENT OF TELANGANA
E12: IRRIGATION & CAD DEPARTMENT
F14: NAME OF WORK :
C15: Name of Work : Repairs and Reconstruction of the Protection Wall and Inlet/Outlet Wing Walls of the U.T. at Km 8.388 of Mulkalakalva Major of NSLBC, Block-IV, at Alagadapa (V), Miryalaguda (M), Nalgonda District.
D17: AMOUNT OF ESTIMATE
C18: , | G18: Rs | H18: ='Abstract '!G22 -> 9.7822103 | J18: Lakhs

Sheet Abstract 
A1: ABSTRACT ESTIMATE
A2: Name of Work : Repairs and Reconstruction of the Protection Wall and Inlet/Outlet Wing Walls of the U.T. at Km 8.388 of Mulkalakalva Major of NSLBC, Block-IV, at Alagadapa (V), Miryalaguda (M), Nalgonda District.
A3: S.No | B3: Item Code | C3: Description of Item | D3: QTY | E3: Unit Rate | F3: Unit | G3: Amount
A4: 1 | B4: =Detail!B4 -> TBSC-U.I-01 (Item No 1129) | C4: Dismantling of Stone masonry in cement mortar for UT walls at inlet/ outlet and Damaged Protection walls | D4: =Detail!J9 -> 24.84 | E4: ='Datas - 2026-27'!H10 -> 765.8 | F4: ='Datas - 2026-27'!E7 -> Cum | G4: =D4*E4 -> 19022.472
A5: 2 | B5: IRR-CCDW-1-2 | C5: Excavation for Structures- Mechanical Means (Data adopted from MORTH ) Earth work in excavation in all kinds of foundation of structures as per drawing and technical specification including setting out. Construction of shoring and bracing, removal of stumps and other deleterious matter, dressing of sides and bottom and backfilling with approved material depth upto 3 meters) | D5: =Detail!J14 -> 103 | E5: ='Datas - 2026-27'!H45 -> 136.9 | F5: ='Datas - 2026-27'!H48 -> Cum | G5: =D5*E5 -> 14100.7
A6: 3 | B6: IRR-CCDW-2-3 | C6: Providing and laying insitu vibrated M-15 ( 28 days cube compressive strength not less than 15 N /sq mm ) grade cement concrete using 40 mm down size approved, clean, hard, gradedaggregates for foundation filling including cost of all materials, machinery, labour, formwork,cleaning, batching, mixing, placing in position, levelling, vibrating, finishing, curing etc.,complete with initial lead upto 50 m and all lifts. | D6: =Detail!J21 -> 27.16 | E6: ='Datas - 2026-27'!H114 -> 6649.3 | F6: ='Datas - 2026-27'!H48 -> Cum | G6: =D6*E6 -> 180594.99
A7: 4 | B7: ='Datas - 2026-27'!B116 -> SOR page no.647 of 806 | C7: Manufacture and supply & delivery of RCC socket and spigot pipes conforming to BIS 458/ 2003 at expactory (Rate per meter of effective length ) excluding transportion taxes and duties 300 mm dia NP2 pipes | D7: =Detail!J24 -> 10 | E7: ='Datas - 2026-27'!H122 -> 1771.6423 | F7: ='Datas - 2026-27'!E118 -> RM | G7: =D7*E7 -> 17716.423
A8: 5 | B8: ='Datas - 2026-27'!B124 -> IRR-CCDW-6-1 | C8: Laying and jointing 300 mm dia. NP- 2 class or IRC standard hume pipes in CM 1 : 2 proportion by volume including cost of all materials ( excluding pipes and collars ), machinery, labour, aligning, packing joints with hemp, finishing, curing etc., complete with initial lead upto 50 m and all lifts. (Cement content: 9.9 kg / joint, FA : 0.01cum/joint, Hemp Yarn : 0.091kg/joint) | D8: =Detail!J27 -> 4 | E8: ='Datas - 2026-27'!H157 -> 602.58 | F8: ='Datas - 2026-27'!H125 -> Joints | G8: =D8*E8 -> 2410.32
A9: 6 | B9: ='Datas - 2026-27'!B159 -> IRR-CCDW-2-9 | C9: Providing and laying insitu vibrated M-15 ( 28 days cube compressive strength not less than15 N / sq mm ) grade cement concrete using 40 mm down size approved, clean, hard, gradedaggregates for sub-structure / super- structure works including cost of all materials,machinery, labour, formwork, scaffolding, cleaning, batching, mixing, placing in position,levelling, vibrating, finishing, curing etc., complete with initial lead upto 50 m and all lifts. | D9: =Detail!J31 -> 76.95 | E9: ='Datas - 2026-27'!H224 -> 6990.9 | F9: ='Datas - 2026-27'!H160 -> Cum | G9: =D9*E9 -> 537949.76
A10: 7 | B10: ='Datas - 2026-27'!B226 -> IRR-PMW-3-17 | C10: Providing casing embankment using semi-pervious soil available from excavation in layers of 25 to 30 cmbefore compaction including cost of all materials, machinery, labour, all other operations such as re-excavation, sorting out, transportation, spreading in layers of specified thickness, breaking clods, sectioning, watering, compacting to specified density control of not less than 95 percent using Sheep footroller / Vibratory roller/ 8 to 10 tonne power roller as stipulated etc.,complete with initial lead upto 1 km and all lifts. | D10: =Detail!J35 -> 76.14 | E10: ='Datas - 2026-27'!H266 -> 220.6 | F10: ='Datas - 2026-27'!H227 -> Cum | G10: =D10*E10 -> 16796.484
D11: E.C.V | G11: =SUM(G4:G10) -> 788591.14
B12: L.S | C12: Provision for Labour Cess @ 1% | D12: L.S | E12: L.S | F12: L.S | G12: =ROUND((G$11*1%),2) -> 7885.91
B13: L.S | C13: Provision for NAC @ 0.1% | D13: L.S | E13: L.S | F13: L.S | G13: =ROUND((G$11*0.1%),2) -> 788.59
B14: L.S | C14: Provision for seignorage charges | D14: L.S | E14: L.S | F14: L.S | G14: ='Seignorage (2)'!G11 -> 15598.26
B15: L.S | C15: Provision For DMF @ 30% on Seigniorage Charges | D15: L.S | E15: L.S | F15: L.S | G15: ='Seignorage (2)'!G13 -> 4679
B16: L.S | C16: Provision For SMET @ 2% on Seigniorage Charges | D16: L.S | E16: L.S | F16: L.S | G16: ='Seignorage (2)'!G12 -> 312
C17: Permit Fee Payable | D17: L.S | E17: L.S | F17: L.S | G17: ='Seignorage (2)'!G14 -> 11145.968
G18: =G11+G12+G13+G14+G15+G16+G17 -> 829000.87
C19: Provision towards GST @ 18% | D19: L.S | E19: L.S | F19: L.S | G19: =ROUND((G$18*18%),2) -> 149220.16
B20: L.S | C20: Provision towards other miscellaneous items | D20: L.S | E20: L.S | F20: L.S
D21: TOTAL | G21: =SUM(G18:G20) -> 978221.03
C22: Total Amount In Lakhs | G22: =G21/100000 -> 9.7822103

Sheet Detail
A1: ='COVER (2)'!C15 -> Name of Work : Repairs and Reconstruction of the Protection Wall and Inlet/Outlet Wing Walls of the U.T. at Km 8.388 of Mulkalakalva Major of NSLBC, Block-IV, at Alagadapa (V), Miryalaguda (M), Nalgonda District.
C2: Detailed Estimate
A3: S.No | B3: Item code | C3: Description of item | D3: Nos | G3: Length | H3: Breadth | I3: Depth | J3: Quantity | K3: Unit
A4: 1 | B4: TBSC-U.I-01 (Item No 1129) | C4: Dismantling of Stone masonry in cement mortar for UT walls at inlet/ outlet and Damaged Protection walls
C5: UT walls at inlet/ outlet | D5: 2 | E5: X | F5: 2 | G5: 3 | H5: 0.45 | I5: 0.9 | J5: =G5*F5*D5*H5*I5 -> 4.86
C6: Damaged Protection walls | D6: 1 | E6: X | F6: 1 | G6: 17 | H6: 0.45 | I6: 1.2 | J6: =G6*F6*D6*H6*I6 -> 9.18
C7: Damaged Protection walls | D7: 1 | E7: X | F7: 1 | G7: 20 | H7: 0.45 | I7: 1.2 | J7: =G7*F7*D7*H7*I7 -> 10.8
H8: Total | J8: =J5+J6+J7 -> 24.84 | K8: Cum
I9: Or say | J9: =ROUND(J8,2) -> 24.84 | K9: Cum
A10: 2 | B10: IRR-CCDW-1-2 | C10: Excavation for Structures- Mechanical Means (Data adopted from MORTH ) Earth work in excavation in all kinds of foundation of structures as per drawing and technical specification including setting out. Construction of shoring and bracing, removal of stumps and other deleterious matter, dressing of sides and bottom and backfilling with approved material depth upto 3 meters)
C11: at UT @ Km 8.388 wing walls at bank toe | D11: 2 | E11: x | F11: 2 | G11: 5 | H11: 1.8 | I11: 1 | J11: =D11*F11*G11*H11*I11 -> 36
C12: at UT @ Km 8.388 Protection wall | D12: 1 | E12: x | F12: 1 | G12: 37 | H12: 1.8 | I12: 1 | J12: =D12*F12*G12*H12*I12 -> 66.6
I13: Total | J13: =SUM(J11:J12) -> 102.6 | K13: Cum
I14: Or say | J14: =ROUND(J13,0) -> 103 | K14: Cum
A15: 3 | B15: IRR-CCDW-2-3 | C15: Providing and laying insitu vibrated M-15 ( 28 days cube compressive strength not less than 15 N /sq mm ) grade cement concrete using 40 mm down size approved, clean, hard, graded aggregates for foundation filling including cost of all materials, machinery, labour, formwork,cleaning, batching, mixing, placing in position, levelling, vibrating, finishing, curing etc.,complete with initial lead upto 50 m and all lifts.
C16: at UT @Km 8.388 Abutment | D16: 2 | E16: x | F16: 2 | G16: 5 | H16: 1.5 | I16: 0.3 | J16: =D16*F16*G16*H16*I16 -> 9
C17: at inlet and oout let of the UT | D17: 1 | E17: x | F17: 2 | G17: 1.2 | H17: 1.5 | I17: 0.3 | J17: =D17*F17*G17*H17*I17 -> 1.08
C18: Cut off beam | D18: 1 | E18: x | F18: 2 | G18: 1.2 | H18: 0.3 | I18: 0.6 | J18: =D18*F18*G18*H18*I18 -> 0.432
C19: Protection wall | D19: 1 | E19: x | F19: 1 | G19: 37 | H19: 1.5 | I19: 0.3 | J19: =D19*F19*G19*H19*I19 -> 16.65
H20: Total | J20: =SUM(J16:J19) -> 27.162 | K20: Cum
I21: Or say | J21: =ROUND(J20,2) -> 27.16 | K21: Cum
A22: 4 | B22: SOR page no.647 of 806 | C22: Manufacture and supply & delivery of RCC socket and spigot pipes conforming to BIS 458/ 2003 at expactory (Rate per meter of effective length ) excluding transportion taxes and duties 300 mm dia NP2 pipes
C23: supply & delivery of RCC socket and spigot pipes at the outer ends of the UT to replace the damaged one | D23: 2 | E23: X | F23: 2 | G23: 2.5 | J23: =G23*F23*D23 -> 10
H24: Total | J24: =J23 -> 10 | K24: Rmt
A25: 5 | B25: IRR-CCDW-6-1 | C25: Laying and jointing 300 mm dia. NP- 3 class or IRC standard hume pipes in CM 1 : 2 proportion by volume including cost of all materials ( excluding pipes and collars ), machinery, labour, aligning, packing joints with hemp, finishing, curing etc., complete with initial lead upto 50 m and all lifts.
C26: Laying and jointing 300 mm dia. NP- 3 class | D26: 2 | E26: X | F26: 2 | J26: =F26*D26 -> 4
H27: Total | J27: =J26 -> 4 | K27: Joints
A28: 6 | B28: IRR-CCDW-2-9 | C28: Providing and laying insitu vibrated M-15 ( 28 days cube compressive strength not less than15 N / sq mm ) grade cement concrete using 40 mm down size approved, clean, hard, gradedaggregates for sub-structure / super- structure works including cost of all materials,machinery, labour, formwork, scaffolding, cleaning, batching, mixing, placing in position,levelling, vibrating, finishing, curing etc., complete with initial lead upto 50 m and all lifts.
C29: at UT @Km 8.388 Abutment | D29: 2 | E29: x | F29: 2 | G29: 5 | H29: (1.20+0.30)/2 | I29: 1.8 | J29: =D29*F29*G29*(1.2+0.3)/2*I29 -> 27
D30: 1 | E30: x | F30: 1 | G30: 37 | H30: (1.20+0.30)/2 | I30: 1.8 | J30: =D30*F30*G30*(1.2+0.3)/2*I30 -> 49.95
H31: Total | J31: =SUM(J29:J30) -> 76.95 | K31: cum
A32: 7 | B32: IRR-PMW-3-17 | C32: Providing casing embankment using semi-pervious soil available from excavation in layers of 25 to 30 cmbefore compaction including cost of all materials, machinery, labour, all other operations such as re-excavation, sorting out, transportation, spreading in layers of specified thickness, breaking clods, sectioning, watering, compacting to specified density control of not less than 95 percent using Sheep footroller / Vibratory roller/ 8 to 10 tonne power roller as stipulated etc.,complete with initial lead upto 1 km and all lifts.
D33: 1 | E33: x | F33: 2 | G33: 5 | H33: (1.20+1.5)/2 | I33: 1.2 | J33: =D33*F33*G33*(1.2+1.5)/2*I33 -> 16.2
D34: 1 | E34: x | F34: 1 | G34: 37 | H34: (1.20+1.50)/2 | I34: 1.2 | J34: =D34*F34*G34*(1.2+1.5)/2*I34 -> 59.94
H35: Total | J35: =SUM(J33:J34) -> 76.14 | K35: Cum

Sheet Datas - 2026-27
A1: =Detail!A1:K1 -> Name of Work : Repairs and Reconstruction of the Protection Wall and Inlet/Outlet Wing Walls of the U.T. at Km 8.388 of Mulkalakalva Major of NSLBC, Block-IV, at Alagadapa (V), Miryalaguda (M), Nalgonda District.
A2: STANDARD DATA
A3: (SSR 2026-27)
A5: 1 | B5: TBSC-U.I-01 (Item No 1129) | C5: Dismantling Stone masonry in cement mortar
B6: DATA | C6: Description | E6: Unit | F6: Quantity | G6: Rate Rs. | H6: Amount in Rs.
C7: Dismantling Stone masonry in cement mortar | E7: Cum | F7: 1 | G7: 674 | H7: =G7 -> 674
C8: Add contractors Profit and overheads on Material 13.615% | H8: =13.615%*H7 -> 91.7651
C9: Total cost | H9: =SUM(H7:H8) -> 765.7651
C10: Total cost per 1 Cum | H10: =ROUND(H9,1) -> 765.8
A12: 2 | B12: IRR-CCDW-1-2 | C12: Earth work in excavation in all kinds of soils of foundation of structures as per drawing and technical specification, including setting out, construction of shoring and bracing, removal of stumps and other deleterious matter, dressing of sides and bottom and backfilling with approved material. Depth upto 3 m
B13: DATA | D13: RATE ANALYSIS | F13: UNIT | G13: 240 | H13: cum
C15: A. Materials: | H15: 0
C17: Sl No | D17: Description | E17: Unit | F17: Quantity | G17: Rate | H17: Amount
G18: in Rs. | H18: in Rs.
C19: 1 | D19: NIL | F19: 0 | G19: 0 | H19: 0
C20: B.Machinery:
C21: Sl No | D21: Description | E21: Unit | F21: Quantity | G21: Rate | H21: Amount
G22: in Rs. | H22: in Rs.
C23: 1 | D23: Hydraulic excavator 1.0 cum bucket capacity | E23: hour | F23: 6 | G23: 1964.8 | H23: =F23*G23 -> 11788.8
D24: Fuel/ Energy charges | E24: hour | F24: 6 | G24: 1570.3 | H24: =F24*G24 -> 9421.8
D25: Total in Rs. | H25: =SUM(H23:H24) -> 21210.6
C26: C.Labour:
C27: Sl No | D27: Description | E27: Unit | F27: Quantity | G27: Rate | H27: Amount
G28: in Rs. | H28: in Rs.
C29: 1 | D29: work inspector | E29: day | F29: 0.32 | G29: 845 | H29: =F29*G29 -> 270.4
C30: 2 | D30: Mazdoor | E30: day | F30: 8 | G30: 635 | H30: =F30*G30 -> 5080
C31: 3 | D31: crew for excavator | E31: hour | F31: 6 | G31: 392.6 | H31: =F31*G31 -> 2355.6
D32: Total in Rs. | H32: =SUM(H29:H31) -> 7706
D33: labour component/unit qty | G33: =H32/G13 -> 32.108333
D34: Add contractor's profit and overhead charges | F34: 0.13615 | G34: =G33*F34 -> 4.3715496
C35: labour component/unit qty (including contractor's profit) | G35: =SUM(G33:G34) -> 36.479883
D37: Abstract
D38: a) Material | G38: Rs | H38: 0
D39: b) Machinery | G39: Rs | H39: =H25 -> 21210.6
D40: c) Labour | G40: Rs | H40: =H32 -> 7706
D41: Total | G41: Rs | H41: =SUM(H38:H40) -> 28916.6
D42: D. Add for contractor's profit and overheads on (A+B+C) | E42: 0.13615 | G42: Rs: | H42: =ROUND(H41*E42,2) -> 3937
D43: Total cost for | E43: 240 | F43: cum | G43: Rs: | H43: =H42+H41 -> 32853.6
D44: Rate per | E44: cum | G44: Rs. | H44: =H43/E43 -> 136.89
G45: or say Rs. | H45: =ROUND(H44,1) -> 136.9
...

Sheet Quarry Map (2)
A1: Name of Work : Repairs and Reconstruction of the Protection Wall and Inlet/Outlet Wing Walls of the U.T. at Km 8.388 of Mulkalakalva Major of NSLBC, Block-IV, at Alagadapa (V), Miryalaguda (M), Nalgonda District.
G2: Appannapeta metal quarry
G4: Musi River for sand
G9: Proposed site
E10: UT at 8.388 on Mulkala Kaluva Major
C14: Nalgonda to | E14: Miryalaguda to Huzurnagar road
C17: Nalgonda | H17: Miryalaguda
N19: Lead in KM
N20: Metal | O20: 25
B21: Note: Map not to scale | N21: Sand | O21: 16
N22: Pipes | O22: 50

Sheet Lead  (2)
A1: LEAD STATEMENT
A2: Name of Work : Repairs and Reconstruction of the Protection Wall and Inlet/Outlet Wing Walls of the U.T. at Km 8.388 of Mulkalakalva Major of NSLBC, Block-IV, at Alagadapa (V), Miryalaguda (M), Nalgonda District.
A3: Sl. No. | B3: Name of Material | C3: Name of Source | D3: Unit | E3: Distance | G3: Total Distance | H3: Initial Lead upto 1km | I3: Up to 5 Kms Lead | J3: for Every km beyond 5 km upto 30 km | K3: for Every km beyond 30 km | L3: For Every 1 km after 5 km | M3: Total Rs.
E4: MR | F4: CT
A5: 1 | B5: Cement | C5: Local | D5: 1 MT | E5: C.Memo.No.146/Cement&Steel/T3/2024-25 Dated: 27.11.2024 | M5: 5100
A6: 2 | B6: Fine Aggregate/ Sand | C6: Tahadakamalla (Musi) | D6: 1 Cum | E6: 16 | F6: - | G6: 16 | H6: 48.2 | I6: 128.6 | J6: 19.3 | K6: 16.1 | L6: - | M6: =I6-H6+(G6-5)*J6 -> 292.7
A7: 3 | B7: Coarse Aggregate | C7: Appanapeta | D7: 1 Cum | E7: 25 | F7: - | G7: =E7 -> 25 | H7: 46.5 | I7: 128.6 | J7: =J6 -> 19.3 | K7: =K6 -> 16.1 | L7: - | M7: =((I7-H7)+(J7*(G7-5))) -> 468.1
A8: 4 | B8: Gravel | C8: LOCAL | D8: CUM | E8: 5 | F8: - | G8: 5 | H8: 48.2 | I8: 128.6 | J8: 19.3 | K8: 16.1 | M8: =(I8-H8) -> 80.4
A9: 5 | B9: RCC Pipes | C9: Cherlapalli Nalgonda | D9: RMT | E9: 50 | F9: _ | G9: 50 | H9: _ | I9: 73.91 | J9: 2.33 | K9: 2.33 | L9: 2.33 | M9: =I9+(J9*45) -> 178.76
A11: 1 | B11: Certified that the leads furnished above are correct to the best of my knowledge
A12: 2 | B12: Certified that the blasting is necessary to obtain rubble and metal.
A13: 3 | B13: Certified that the extra seigniorage charges added in the estimate as per G.O.Ms.No.14 Dt.08.07.2025 Insudsties and Commerce
A14: 4 | B14: Certified that the leads are taken from the shortest route from the work spot.

Sheet Seignorage (2)
A1: Name of Work :Repairs and Reconstruction of the Protection Wall and Inlet/Outlet Wing Walls of the U.T. at Km 8.388 of Mulkalakalva Major of NSLBC, Block-IV, at Alagadapa (V), Miryalaguda (M), Nalgonda District.
A2: Seignioprage Charges
A3: S.No | B3: Item of Work | C3: Qty | D3: coefficient | E3: Rate | F3: Amount of Deduction
A4: 1 | B4: M15 Bed
B5: Metal | C5: =Detail!J20 -> 27.162 | D5: 0.9 | E5: 117 | G5: =ROUNDUP(C5*D5*E5,2) -> 2860.16
B6: Sand | C6: =C5 -> 27.162 | D6: 0.4 | E6: 40 | G6: =ROUNDUP(C6*D6*E6,2) -> 434.6
A7: 2 | B7: M-15 Sup
B8: Metal | C8: =Detail!J31 -> 76.95 | D8: 0.9 | E8: =E5 -> 117 | G8: =ROUNDUP(C8*D8*E8,2) -> 8102.84
B9: Sand | C9: =C8 -> 76.95 | D9: 0.4 | E9: 40 | G9: =ROUNDUP(C9*D9*E9,2) -> 1231.2
A10: 3 | B10: Earth | C10: =Detail!J35 -> 76.14 | D10: 1 | E10: 39 | G10: =ROUNDUP(C10*D10*E10,2) -> 2969.46
F11: Total | G11: =SUM(G5:G10) -> 15598.26
E12: SMET @ 2% | G12: =ROUND(G11*2%,0) -> 312
E13: DMF @ 30% | G13: =ROUND(G11*30%,0) -> 4679
B14: Permit Fee Payable | D14: 0.8*(4264.65+7107.75+3159) | G14: =0.8*(G5+G8+G10) -> 11145.968

Sheet Certificates
A1: CERTIFICATES
A2: Name of Work : Repairs and Reconstruction of the Protection Wall and Inlet/Outlet Wing Walls of the U.T. at Km 8.388 of Mulkalakalva Major of NSLBC, Block-IV, at Alagadapa (V), Miryalaguda (M), Nalgonda District.
A3: 1 | B3: Site inspected by me; estimate prepared on actual site conditions and measurements taken at site
A4: 2 | B4: Quantities in the detailed estimate are correct and as per drawings/designs enclosed
A5: 3 | B5: Rates as per Standard Data and Common SoR in force; latest cement and steel rates adopted
A6: 4 | B6: Seigniorage allowed as per G.O.s in force; DMF, SMET and permit fee provided at prescribed percentages
A7: 5 | B7: Nearest sources adopted for lead; sufficient quantity available at quarry; shortest route
A8: 6 | B8: No departmental material proposed to be issued
A9: 7 | B9: Provisions adequate; no provision made in any other estimate for the same work
A10: 8 | B10: Work is essential to restore the U.T. and protect the canal bank from further damage
